Workbook

Sheet Index
A1: No. | B1: Pay_item_number | C1: Description | D1: EQR Page
A2: 1 | B2: 0635 2 11 | C2: PULL & SPLICE BOX, F&I, 13" x 24" COVER SIZE | D2: 2
A3: 2 | B3: 0104 18 | C3: INLET PROTECTION SYSTEM | D3: 11
A4: 3 | B4: 0107 1 | C4: LITTER REMOVAL | D4: 13
A5: 4 | B5: 0107 2 | C5: MOWING | D5: 13
A6: 5 | B6: 0110 4 10 | C6: REMOVAL OF EXISTING CONCRETE | D6: 14
A7: 6 | B7: 0110 1 1 | C7: CLEARING & GRUBBING | D7: 14
A8: 7 | B8: 0110 4 10 | C8: REMOVAL OF EXISTING CONCRETE | D8: 17
A9: 8 | B9: 0110 1 1 | C9: CLEARING & GRUBBING | D9: 17
A10: 9 | B10: 0425 1451 | C10: INLETS, CURB, TYPE J-5, <10' | D10: 19
A11: 10 | B11: 0425 5 | C11: MANHOLE, ADJUST | D11: 20
A12: 11 | B12: 0632 7 1 | C12: SIGNAL CABLE- NEW OR RECONSTRUCTED INTERSECTION, FURNISH & INSTALL | D12: 32
A13: 12 | B13: 0632 7 6 | C13: SIGNAL CABLE, REMOVE- INTERSECTION | D13: 32
... A32: 22 | B32: 0650 1 60 | C32: VEHICULAR TRAFFIC SIGNAL, REMOVE- POLES TO REMAIN | D32: 36

Sheet 0635 2 11_x0009_PULL & SPLICE BOX, F&
A1: Final Measure :0635 2 11 PULL & SPLICE BOX, F&I, 13 X 24 COVER SIZE | N1: Ir al Indice
N2: Ir a Pag. 2
A3: Pay Item Number | B3: Pay Item Description | C3: Units of Measure | D3: Quantity | F3: Total Quantity | H3: Location
D4: P | E4: F | F4: P | G4: F | H4: Alignment | I4: Beging Sta. | J4: End Sta. | K4: Side | L4: Description: | M4: Estimate#:
A5: Column1 | B5: Column2 | C5: Column3 | D5: Column4 | E5: Column5 | F5: Column6 | G5: Column7 | H5: Column8 | I5: Column9 | J5: Column10 | K5: Column11 | L5: Column12 | M5: Column13
A6: ='Page 2'!A4 -> 0635 2 11 | B6: ='Page 2'!B4 -> Pull & Splice Box, F&I, 13 X 24 Cover Size | C6: ='Page 2'!D4 -> EA | D6: 1 | E6: 1 | F6: ='Page 2'!G4 -> 3 | G6: ='Page 2'!H4 -> 0 | H6: ='Page 2'!L4 -> BLSR976 | I6: ='Page 2'!M4 -> 412+70.26 | J6: ='Page 2'!N4 -> 412+70.26 | K6: ='Page 2'!O4 -> RT
D7: ='Page 2'!E5 -> 1 | E7: 1 | F7: ='Page 2'!G5 -> 0 | G7: ='Page 2'!H5 -> 0 | H7: ='Page 2'!L5 -> BLSR976 | I7: ='Page 2'!M5 -> 413+47.53 | J7: ='Page 2'!N5 -> 413+47.53 | K7: ='Page 2'!O5 -> RT
D8: ='Page 2'!E6 -> 1 | E8: 1 | F8: ='Page 2'!G6 -> 0 | G8: ='Page 2'!H6 -> 0 | H8: ='Page 2'!L6 -> BLSR976 | I8: ='Page 2'!M6 -> 414+35.31 | J8: ='Page 2'!N6 -> 414+35.31 | K8: ='Page 2'!O6 -> RT
A43: Sub-Total: | D43: =SUM(D6:D42) -> 3 | E43: =SUM(E6:E42) -> 3
C45: Date:

Sheet 0104 18_x0009_INLET PROTECTION SYST
A1: Final Measure : 0104 18 INLET PROTECTION SYSTEM | N1: Ir al Indice
N2: Ir a Pag. 11
A3: Pay Item Number | B3: Pay Item Description | C3: Units of Measure | D3: Quantity | F3: Total Quantity | H3: Location
D4: P | E4: F | F4: P | G4: F | H4: Alignment | I4: Beging Sta. | J4: End Sta. | K4: Side | L4: Description: | M4: Estimate#:
A5: Column1 | B5: Column2 | C5: Column3 | D5: Column4 | E5: Column5 | F5: Column6 | G5: Column7 | H5: Column8 | I5: Column9 | J5: Column10 | K5: Column11 | L5: Column12 | M5: Column13
A6: ='Page 11'!A4 -> 0104 18 | B6: ='Page 11'!B4 -> Inlet Protection System | C6: ='Page 11'!D4 -> EA | D6: ='Page 11'!E4 -> 1 | E6: 1 | F6: ='Page 11'!G4 -> 35 | G6: ='Page 11'!H4 -> 0 | H6: ='Page 11'!I4 -> BLSR976 | I6: ='Page 11'!J4 -> 411+42.40 | J6: ='Page 11'!K4 -> 411+53.25 | K6: ='Page 11'!L4 -> RT
D7: ='Page 11'!E5 -> 1 | E7: 1 | F7: ='Page 11'!G5 -> 0 | G7: ='Page 11'!H5 -> 0 | H7: ='Page 11'!I5 -> BLSR976 | I7: ='Page 11'!J5 -> 411+91.82 | J7: ='Page 11'!K5 -> 412+02.66 | K7: ='Page 11'!L5 -> LT
D8: ='Page 11'!E6 -> 1 | E8: 1 | F8: ='Page 11'!G6 -> 0 | G8: ='Page 11'!H6 -> 0 | H8: ='Page 11'!I6 -> BLSR976 | I8: ='Page 11'!J6 -> 413+45.44 | J8: ='Page 11'!K6 -> 413+56.41 | K8: ='Page 11'!L6 -> RT
D9: ='Page 11'!E7 -> 1 | E9: 1 | F9: ='Page 11'!G7 -> 0 | G9: ='Page 11'!H7 -> 0 | H9: ='Page 11'!I7 -> BLSR976 | I9: ='Page 11'!J7 -> 413+53.31 | J9: ='Page 11'!K7 -> 413+64.16 | K9: ='Page 11'!L7 -> LT
D10: ='Page 11'!E8 -> 1 | E10: 1 | F10: ='Page 11'!G8 -> 0 | G10: ='Page 11'!H8 -> 0 | H10: ='Page 11'!I8 -> BLSR976 | I10: ='Page 11'!J8 -> 418+46.66 | J10: ='Page 11'!K8 -> 418+57.22 | K10: ='Page 11'!L8 -> RT
D11: ='Page 11'!E9 -> 1 | E11: 1 | F11: ='Page 11'!G9 -> 0 | G11: ='Page 11'!H9 -> 0 | H11: ='Page 11'!I9 -> BLSR976 | I11: ='Page 11'!J9 -> 419+25.89 | J11: ='Page 11'!K9 -> 419+36.28 | K11: ='Page 11'!L9 -> RT
D12: ='Page 11'!E10 -> 1 | E12: 1 | F12: ='Page 11'!G10 -> 0 | G12: ='Page 11'!H10 -> 0 | H12: ='Page 11'!I10 -> BLSR976 | I12: ='Page 11'!J10 -> 419+90.30 | J12: ='Page 11'!K10 -> 420+06.43 | K12: ='Page 11'!L10 -> LT
D13: ='Page 11'!E11 -> 1 | E13: 1 | F13: ='Page 11'!G11 -> 0 | G13: ='Page 11'!H11 -> 0 | H13: ='Page 11'!I11 -> BLSR976 | I13: ='Page 11'!J11 -> 420+44.54 | J13: ='Page 11'!K11 -> 420+55.01 | K13: ='Page 11'!L11 -> LT
D14: ='Page 11'!E12 -> 1 | E14: 1 | F14: ='Page 11'!G12 -> 0 | G14: ='Page 11'!H12 -> 0 | H14: ='Page 11'!I12 -> BLSR976 | I14: ='Page 11'!J12 -> 421+41.36 | J14: ='Page 11'!K12 -> 421+41.91 | K14: ='Page 11'!L12 -> LT
D15: ='Page 11'!E13 -> 1 | E15: 1 | F15: ='Page 11'!G13 -> 0 | G15: ='Page 11'!H13 -> 0 | H15: ='Page 11'!I13 -> BLSR976 | I15: ='Page 11'!J13 -> 421+56.86 | J15: ='Page 11'!K13 -> 421+57.30 | K15: ='Page 11'!L13 -> RT
D16: ='Page 11'!E14 -> 1 | E16: 1 | F16: ='Page 11'!G14 -> 0 | G16: ='Page 11'!H14 -> 0 | H16: ='Page 11'!I14 -> BLSR976 | I16: ='Page 11'!J14 -> 421+59.30 | J16: ='Page 11'!K14 -> 421+59.46 | K16: ='Page 11'!L14 -> RT
D17: ='Page 11'!E15 -> 1 | E17: 1 | F17: ='Page 11'!G15 -> 0 | G17: ='Page 11'!H15 -> 0 | H17: ='Page 11'!I15 -> BLSR976 | I17: ='Page 11'!J15 -> 422+24.32 | J17: ='Page 11'!K15 -> 422+24.88 | K17: ='Page 11'!L15 -> LT
D18: ='Page 11'!E16 -> 1 | E18: 1 | F18: ='Page 11'!G16 -> 0 | G18: ='Page 11'!H16 -> 0 | H18: ='Page 11'!I16 -> BLSR976 | I18: ='Page 11'!J16 -> 422+32.16 | J18: ='Page 11'!K16 -> 422+32.32 | K18: ='Page 11'!L16 -> RT
... D36: ='Page 11'!E34 -> 1 | E36: 1 | F36: ='Page 11'!G34 -> 0 | G36: ='Page 11'!H34 -> 0 | H36: ='Page 11'!I34 -> BLSR976 | I36: ='Page 11'!J34 -> 429+62.65 | J36: ='Page 11'!K34 -> 429+68.65 | K36: ='Page 11'!L34 -> LT
D37: ='Page 12'!E4 -> 1 | E37: 1 | F37: ='Page 12'!G4 -> 0 | G37: ='Page 12'!H4 -> 0 | H37: ='Page 12'!I4 -> BLSR976 | I37: ='Page 12'!J4 -> 429+68.66 | J37: ='Page 12'!K4 -> 429+74.66 | K37: ='Page 12'!L4 -> LT
D38: ='Page 12'!E5 -> 1 | E38: 1 | F38: ='Page 12'!G5 -> 0 | G38: ='Page 12'!H5 -> 0 | H38: ='Page 12'!I5 -> BLSR976 | I38: ='Page 12'!J5 -> 429+74.66 | J38: ='Page 12'!K5 -> 429+80.66 | K38: ='Page 12'!L5 -> LT
D39: ='Page 12'!E6 -> 1 | E39: 1 | F39: ='Page 12'!G6 -> 0 | G39: ='Page 12'!H6 -> 0 | H39: ='Page 12'!I6 -> BLSR976 | I39: ='Page 12'!J6 -> 429+80.66 | J39: ='Page 12'!K6 -> 429+86.66 | K39: ='Page 12'!L6 -> LT
D40: ='Page 12'!E7 -> 1 | E40: 1 | F40: ='Page 12'!G7 -> 0 | G40: ='Page 12'!H7 -> 0 | H40: ='Page 12'!I7 -> BLSR976 | I40: ='Page 12'!J7 -> 429+86.66 | J40: ='Page 12'!K7 -> 429+92.66 | K40: ='Page 12'!L7 -> LT
A43: Sub-Total: | D43: =SUM(D6:D42) -> 35 | E43: =SUM(E6:E42) -> 35
C45: Date:

Sheet _x0009_0107  1_x0009_LITTER REMOVAL
A1: Final Measure : 2 0107 1 LITTER REMOVAL AND DISPOSAL | N1: Ir al Indice
N2: Ir a Pag 13
A3: Pay Item Number | B3: Pay Item Description | C3: Units of Measure | D3: Quantity | F3: Total Quantity | H3: Location
D4: P | E4: F | F4: P | G4: F | H4: Alignment | I4: Beging Sta. | J4: End Sta. | K4: Side | L4: Description: | M4: Estimate#:
A5: Column1 | B5: Column2 | C5: Column3 | D5: Column4 | E5: Column5 | F5: Column6 | G5: Column7 | H5: Column8 | I5: Column9 | J5: Column10 | K5: Column11 | L5: Column12 | M5: Column13
A6: ='Page 13'!A4 -> 0107 1 | B6: ='Page 13'!B4 -> Litter Removal And Disposal | C6: ='Page 13'!D4 -> AC | D6: ='Page 13'!M4 -> 11.2 | E6: ='Page 13'!N4 -> 0 | F6: ='Page 11'!G4 -> 35 | G6: ='Page 11'!H4 -> 0 | H6: ='Page 13'!P4 -> BLSR976 | I6: ='Page 13'!Q4 -> 412+85.00 | J6: ='Page 13'!R4 -> 428+90.00 | K6: ='Page 13'!S4 -> RT
A7: ='Page 13'!A5 -> 0 | B7: ='Page 13'!B5 -> 0 | C7: ='Page 13'!D5 -> 0 | D7: ='Page 13'!M5 -> 0 | E7: ='Page 13'!N5 -> 0 | F7: ='Page 11'!G5 -> 0 | G7: ='Page 11'!H5 -> 0 | H7: ='Page 13'!P5 -> BLSR976 | I7: ='Page 13'!Q5 -> 412+85.00 | J7: ='Page 13'!R5 -> 428+90.00 | K7: ='Page 13'!S5 -> LT
A8: ='Page 13'!A6 -> 0 | B8: ='Page 13'!B6 -> 0 | C8: ='Page 13'!D6 -> 0 | D8: ='Page 13'!M6 -> 0 | E8: ='Page 13'!N6 -> 0 | F8: ='Page 11'!G6 -> 0 | G8: ='Page 11'!H6 -> 0 | H8: ='Page 13'!P6 -> BLSR976 | I8: ='Page 13'!Q6 -> 412+85.00 | J8: ='Page 13'!R6 -> 428+90.00 | K8: ='Page 13'!S6 -> RT
A43: Sub-Total: | D43: =SUM(D6:D42) -> 11.2 | E43: =SUM(E6:E42) -> 0
C45: Date:

Sheet _x0009_0107  2_x0009_MOWING
A1: Final Measure : 3 0107 2 MOWING | N1: Ir al Indice
N2: Ir a Pag 13
A3: Pay Item Number | B3: Pay Item Description | C3: Units of Measure | D3: Quantity | F3: Total Quantity | H3: Location
D4: P | E4: F | F4: P | G4: F | H4: Alignment | I4: Beging Sta. | J4: End Sta. | K4: Side | L4: Description: | M4: Estimate#:
A5: Column1 | B5: Column2 | C5: Column3 | D5: Column4 | E5: Column5 | F5: Column6 | G5: Column7 | H5: Column8 | I5: Column9 | J5: Column10 | K5: Column11 | L5: Column12 | M5: Column13
A6: ='Page 13'!A7 -> 0107 2 | B6: ='Page 13'!B7 -> Mowing | C6: ='Page 13'!D7 -> AC | D6: ='Page 13'!M7 -> 11.2 | E6: ='Page 13'!N7 -> 0 | H6: ='Page 13'!P7 -> BLSR976 | I6: ='Page 13'!Q7 -> 412+85.00 | J6: ='Page 13'!R7 -> 428+90.00 | K6: ='Page 13'!S7 -> RT
D7: ='Page 13'!M8 -> 0 | E7: ='Page 13'!N8 -> 0 | H7: ='Page 13'!P8 -> BLSR976 | I7: ='Page 13'!Q8 -> 412+85.00 | J7: ='Page 13'!R8 -> 428+90.00 | K7: ='Page 13'!S8 -> LT
D8: ='Page 13'!M9 -> 0 | E8: ='Page 13'!N9 -> 0 | H8: ='Page 13'!P9 -> BLSR976 | I8: ='Page 13'!Q9 -> 412+85.00 | J8: ='Page 13'!R9 -> 428+90.00 | K8: ='Page 13'!S9 -> RT
A43: Sub-Total: | D43: =SUM(Table4674[Column4]) -> 11.2 | E43: =SUM(Table4674[Column5]) -> 0
C45: Date:

Sheet 1_x0009_0110  1  1_x0009_CLEARING & GRUBBIN
A1: Final Measure : Inlet Protection System | N1: Ir al Indice
N2: Ir a Pag 14
A3: Pay Item Number | B3: Pay Item Description | C3: Units of Measure | D3: Quantity | F3: Total Quantity | H3: Location
D4: P | E4: F | F4: P | G4: F | H4: Alignment | I4: Beging Sta. | J4: End Sta. | K4: Side | L4: Description: | M4: Estimate#:
A5: Column1 | B5: Column2 | C5: Column3 | D5: Column4 | E5: Column5 | F5: Column6 | G5: Column7 | H5: Column8 | I5: Column9 | J5: Column10 | K5: Column11 | L5: Column12 | M5: Column13
A6: ='Page 14'!A4 -> 0110 1 1 | B6: ='Page 14'!B4 -> Clearing & Grubbing | C6: ='Page 14'!D4 -> LS | D6: ='Page 14'!G4 -> 1 | E6: ='Page 14'!H4 -> 0 | H6: ='Page 14'!N4 -> BLSR976 | I6: ='Page 14'!O4 -> 418+46.70 | J6: ='Page 14'!P4 -> 418+57.18 | K6: ='Page 14'!Q4 -> RT
D7: ='Page 14'!G5 -> 0 | E7: ='Page 14'!H5 -> 0 | H7: ='Page 14'!N5 -> BLSR976 | I7: ='Page 14'!O5 -> 422+30.27 | J7: ='Page 14'!P5 -> 422+34.41 | K7: ='Page 14'!Q5 -> RT
D8: ='Page 14'!G6 -> 0 | E8: ='Page 14'!H6 -> 0 | H8: ='Page 14'!N6 -> BLSR976 | I8: ='Page 14'!O6 -> 422+44.84 | J8: ='Page 14'!P6 -> 422+54.71 | K8: ='Page 14'!Q6 -> RT
D9: ='Page 14'!G7 -> 0 | E9: ='Page 14'!H7 -> 0 | H9: ='Page 14'!N7 -> BLSR976 | I9: ='Page 14'!O7 -> 422+55.75 | J9: ='Page 14'!P7 -> 422+70.61 | K9: ='Page 14'!Q7 -> RT
D10: ='Page 14'!G8 -> 0 | E10: ='Page 14'!H8 -> 0 | H10: ='Page 14'!N8 -> BLSR976 | I10: ='Page 14'!O8 -> 422+59.29 | J10: ='Page 14'!P8 -> 422+69.17 | K10: ='Page 14'!Q8 -> RT
A43: Sub-Total: | D43: =SUBTOTAL(109,D6:D42) -> 1 | E43: =SUBTOTAL(109,E6:E42) -> 0
C45: Date:

Sheet 1_x0009_0110  4 10_x0009_REMOVAL OF EXIST C
A1: Final Measure : 5 0110 4 10 REMOVAL OF EXIST C | N1: Ir al Indice
N2: Ir a Pag 14
A3: Pay Item Number | B3: Pay Item Description | C3: Units of Measure | D3: Quantity | F3: Total Quantity | H3: Location
D4: P | E4: F | F4: P | G4: F | H4: Alignment | I4: Beging Sta. | J4: End Sta. | K4: Side | L4: Description: | M4: Estimate#:
A5: Column1 | B5: Column2 | C5: Column3 | D5: Column4 | E5: Column5 | F5: Column6 | G5: Column7 | H5: Column8 | I5: Column9 | J5: Column10 | K5: Column11 | L5: Column12 | M5: Column13
A6: ='Page 14'!A9 -> 0110 4 10 | B6: ='Page 14'!B9 -> Removal Of Existing Concrete | C6: ='Page 14'!D9 -> SY | D6: ='Page 14'!G9 -> 20.6 | E6: ='Page 14'!H10 -> 0 | F6: ='Page 11'!G4 -> 35 | G6: ='Page 11'!H4 -> 0 | H6: ='Page 14'!N9 -> BLSR976 | I6: ='Page 14'!O9 -> 412+69.32 | J6: ='Page 14'!P9 -> 412+87.89 | K6: ='Page 14'!Q9 -> RT
D7: ='Page 14'!G10 -> 6.4 | E7: ='Page 14'!H11 -> 0 | F7: ='Page 11'!G5 -> 0 | G7: ='Page 11'!H5 -> 0 | H7: ='Page 14'!N10 -> BLSR976 | I7: ='Page 14'!O10 -> 412+73.98 | J7: ='Page 14'!P10 -> 412+89.88 | K7: ='Page 14'!Q10 -> RT
D8: ='Page 14'!G11 -> 5.3 | E8: ='Page 14'!H12 -> 0 | F8: ='Page 11'!G6 -> 0 | G8: ='Page 11'!H6 -> 0 | H8: ='Page 14'!N11 -> BLSR976 | I8: ='Page 14'!O11 -> 413+29.81 | J8: ='Page 14'!P11 -> 413+45.46 | K8: ='Page 14'!Q11 -> RT
D9: ='Page 14'!G12 -> 23.7 | E9: ='Page 14'!H13 -> 0 | F9: ='Page 11'!G7 -> 0 | G9: ='Page 11'!H7 -> 0 | H9: ='Page 14'!N12 -> BLSR976 | I9: ='Page 14'!O12 -> 413+31.83 | J9: ='Page 14'!P12 -> 413+56.26 | K9: ='Page 14'!Q12 -> RT
D10: ='Page 14'!G13 -> 3.9 | E10: ='Page 14'!H14 -> 0 | F10: ='Page 11'!G8 -> 0 | G10: ='Page 11'!H8 -> 0 | H10: ='Page 14'!N13 -> BLSR976 | I10: ='Page 14'!O13 -> 414+32.27 | J10: ='Page 14'!P13 -> 414+37.14 | K10: ='Page 14'!Q13 -> RT
D11: ='Page 14'!G14 -> 4.1 | E11: ='Page 14'!H15 -> 0 | F11: ='Page 11'!G9 -> 0 | G11: ='Page 11'!H9 -> 0 | H11: ='Page 14'!N14 -> BLSR976 | I11: ='Page 14'!O14 -> 415+70.10 | J11: ='Page 14'!P14 -> 415+86.33 | K11: ='Page 14'!Q14 -> RT
D12: ='Page 14'!G15 -> 9.1 | E12: ='Page 14'!H16 -> 0 | F12: ='Page 11'!G10 -> 0 | G12: ='Page 11'!H10 -> 0 | H12: ='Page 14'!N15 -> BLSR976 | I12: ='Page 14'!O15 -> 415+70.16 | J12: ='Page 14'!P15 -> 415+84.25 | K12: ='Page 14'!Q15 -> RT
D13: ='Page 14'!G16 -> 3.4 | E13: ='Page 14'!H17 -> 0 | F13: ='Page 11'!G11 -> 0 | G13: ='Page 11'!H11 -> 0 | H13: ='Page 14'!N16 -> BLSR976 | I13: ='Page 14'!O16 -> 416+27.09 | J13: ='Page 14'!P16 -> 416+32.06 | K13: ='Page 14'!Q16 -> LT
D14: ='Page 14'!G17 -> 4.4 | E14: ='Page 14'!H18 -> 0 | F14: ='Page 11'!G12 -> 0 | G14: ='Page 11'!H12 -> 0 | H14: ='Page 14'!N17 -> BLSR976 | I14: ='Page 14'!O17 -> 416+35.82 | J14: ='Page 14'!P17 -> 416+41.40 | K14: ='Page 14'!Q17 -> RT
D15: ='Page 14'!G18 -> 7.2 | E15: ='Page 14'!H19 -> 0 | F15: ='Page 11'!G13 -> 0 | G15: ='Page 11'!H13 -> 0 | H15: ='Page 14'!N18 -> BLSR976 | I15: ='Page 14'!O18 -> 416+57.06 | J15: ='Page 14'!P18 -> 416+79.59 | K15: ='Page 14'!Q18 -> LT
D16: ='Page 14'!G19 -> 29.6 | E16: ='Page 14'!H20 -> 0 | F16: ='Page 11'!G14 -> 0 | G16: ='Page 11'!H14 -> 0 | H16: ='Page 14'!N19 -> BLSR976 | I16: ='Page 14'!O19 -> 416+57.11 | J16: ='Page 14'!P19 -> 416+77.58 | K16: ='Page 14'!Q19 -> LT
D17: ='Page 14'!G20 -> 7.9 | E17: ='Page 14'!H21 -> 0 | F17: ='Page 11'!G15 -> 0 | G17: ='Page 11'!H15 -> 0 | H17: ='Page 14'!N20 -> BLSR976 | I17: ='Page 14'!O20 -> 417+03.55 | J17: ='Page 14'!P20 -> 417+29.19 | K17: ='Page 14'!Q20 -> LT
D18: ='Page 14'!G21 -> 20.5 | E18: ='Page 14'!H22 -> 0 | F18: ='Page 11'!G16 -> 0 | G18: ='Page 11'!H16 -> 0 | H18: ='Page 14'!N21 -> BLSR976 | I18: ='Page 14'!O21 -> 417+05.61 | J18: ='Page 14'!P21 -> 417+29.14 | K18: ='Page 14'!Q21 -> LT
... D27: ='Page 14'!G30 -> 1.7 | E27: ='Page 14'!H31 -> 0 | F27: ='Page 11'!G25 -> 0 | G27: ='Page 11'!H25 -> 0 | H27: ='Page 14'!N30 -> BLSR976 | I27: ='Page 14'!O30 -> 420+97.31 | J27: ='Page 14'!P30 -> 421+02.32 | K27: ='Page 14'!Q30 -> RT
D28: ='Page 15'!G4 -> 35 | E28: ='Page 15'!I4 -> 0 | F28: ='Page 15'!J4 -> 0 | G28: ='Page 15'!K4 -> 0 | H28: ='Page 15'!N4 -> BLSR976 | I28: ='Page 15'!O4 -> 421+20.36 | J28: ='Page 15'!P4 -> 421+44.70 | K28: ='Page 15'!Q4 -> LT
D29: ='Page 15'!G5 -> 3.8 | E29: ='Page 15'!H5 -> 0 | F29: ='Page 15'!I5 -> 0 | G29: ='Page 15'!J5 -> 0 | H29: ='Page 15'!N5 -> BLSR976 | I29: ='Page 15'!O5 -> 421+22.19 | J29: ='Page 15'!P5 -> 421+31.01 | K29: ='Page 15'!Q5 -> RT
D30: ='Page 15'!G6 -> 26.2 | E30: ='Page 15'!H6 -> 0 | H30: ='Page 15'!N6 -> BLSR976 | I30: ='Page 15'!O6 -> 421+25.29 | J30: ='Page 15'!P6 -> 421+54.68 | K30: ='Page 15'!Q6 -> RT
D31: ='Page 15'!G7 -> 7.1 | E31: ='Page 15'!H7 -> 0 | H31: ='Page 15'!N7 -> BLSR976 | I31: ='Page 15'!O7 -> 421+25.35 | J31: ='Page 15'!P7 -> 421+46.80 | K31: ='Page 15'!Q7 -> LT
D32: ='Page 15'!G8 -> 5.2 | E32: ='Page 15'!H8 -> 0 | H32: ='Page 15'!N8 -> BLSR976 | I32: ='Page 15'!O8 -> 421+36.21 | J32: ='Page 15'!P8 -> 421+42.00 | K32: ='Page 15'!Q8 -> LT
D33: ='Page 15'!G9 -> 5.1 | E33: ='Page 15'!H9 -> 0 | H33: ='Page 15'!N9 -> BLSR976 | I33: ='Page 15'!O9 -> 421+41.79 | J33: ='Page 15'!P9 -> 421+56.97 | K33: ='Page 15'!Q9 -> RT
D34: ='Page 15'!G10 -> 1.7 | E34: ='Page 15'!H10 -> 0 | H34: ='Page 15'!N10 -> BLSR976 | I34: ='Page 15'!O10 -> 421+90.04 | J34: ='Page 15'!P10 -> 421+93.38 | K34: ='Page 15'!Q10 -> LT
D35: ='Page 15'!G11 -> 2.5 | E35: ='Page 15'!H11 -> 0 | H35: ='Page 15'!N11 -> BLSR976 | I35: ='Page 15'!O11 -> 422+22.03 | J35: ='Page 15'!P11 -> 422+26.83 | K35: ='Page 15'!Q11 -> RT
D36: ='Page 15'!G12 -> 28.6 | E36: ='Page 15'!H12 -> 0 | H36: ='Page 15'!N12 -> BLSR976 | I36: ='Page 15'!O12 -> 422+22.07 | J36: ='Page 15'!P12 -> 422+45.21 | K36: ='Page 15'!Q12 -> RT
D37: ='Page 15'!G13 -> 8.3 | E37: ='Page 15'!H13 -> 0 | H37: ='Page 15'!N13 -> BLSR976 | I37: ='Page 15'!O13 -> 422+22.98 | J37: ='Page 15'!P13 -> 422+51.25 | K37: ='Page 15'!Q13 -> LT
D38: ='Page 15'!G14 -> 28.7 | E38: ='Page 15'!H14 -> 0 | H38: ='Page 15'!N14 -> BLSR976 | I38: ='Page 15'!O14 -> 422+24.54 | J38: ='Page 15'!P14 -> 422+51.27 | K38: ='Page 15'!Q14 -> LT
D39: ='Page 15'!G15 -> 2.7 | E39: ='Page 15'!H15 -> 0 | H39: ='Page 15'!N15 -> BLSR976 | I39: ='Page 15'!O15 -> 422+44.47 | J39: ='Page 15'!P15 -> 422+48.42 | K39: ='Page 15'!Q15 -> RT
D40: ='Page 15'!G16 -> 7.4 | E40: ='Page 15'!H16 -> 0 | H40: ='Page 15'!N16 -> BLSR976 | I40: ='Page 15'!O16 -> 422+45.14 | J40: ='Page 15'!P16 -> 422+57.25 | K40: ='Page 15'!Q16 -> RT
D41: ='Page 15'!G17 -> 6.5 | E41: ='Page 15'!H17 -> 0 | H41: ='Page 15'!N17 -> BLSR976 | I41: ='Page 15'!O17 -> 422+60.22 | J41: ='Page 15'!P17 -> 422+72.00 | K41: ='Page 15'!Q17 -> RT
... D51: ='Page 15'!G27 -> 6.8 | E51: ='Page 15'!H27 -> 0 | H51: ='Page 15'!N27 -> BLSR976 | I51: ='Page 15'!O27 -> 426+65.94 | J51: ='Page 15'!P27 -> 426+76.64 | K51: ='Page 15'!Q27 -> LT
D52: ='Page 16'!G4 -> 4.2 | E52: ='Page 16'!H4 -> 0 | H52: ='Page 16'!N4 -> BLSR976 | I52: ='Page 16'!O4 -> 426+65.95 | J52: ='Page 16'!P4 -> 426+78.88 | K52: ='Page 16'!Q4 -> LT
D53: ='Page 16'!G5 -> 3.5 | E53: ='Page 16'!H5 -> 0 | F53: ='Page 16'!I5 -> 0 | G53: ='Page 16'!J5 -> 0 | H53: ='Page 16'!N5 -> BLSR976 | I53: ='Page 16'!O5 -> 427+06.37 | J53: ='Page 16'!P5 -> 427+20.67 | K53: ='Page 16'!Q5 -> RT
D54: ='Page 16'!G6 -> 7.2 | E54: ='Page 16'!H6 -> 0 | H54: ='Page 16'!N6 -> BLSR976 | I54: ='Page 16'!O6 -> 427+07.41 | J54: ='Page 16'!P6 -> 427+22.34 | K54: ='Page 16'!Q6 -> RT
A55: Sub-Total: | D55: =SUM(D6:D54) -> 501.9 | E55: =SUM(E6:E54) -> 0
C57: Date:

Sheet _x0009_0110  1  2_x0009_CLEARING & GRUBBING
A1: Final Measure : 0110 1 2 CLEARING & GRUBBING | N1: Ir al Indice
N2: Ir a Pag 17
A3: Pay Item Number | B3: Pay Item Description | C3: Units of Measure | D3: Quantity | F3: Total Quantity | H3: Location
D4: P | E4: F | F4: P | G4: F | H4: Alignment | I4: Beging Sta. | J4: End Sta. | K4: Side | L4: Description: | M4: Estimate#:
A5: Column1 | B5: Column2 | C5: Column3 | D5: Column4 | E5: Column5 | F5: Column6 | G5: Column7 | H5: Column8 | I5: Column9 | J5: Column10 | K5: Column11 | L5: Column12 | M5: Column13
A6: ='Page 17'!A4 -> 0110 1 1 | B6: ='Page 17'!B4 -> Clearing & Grubbing | C6: ='Page 17'!D4 -> LS | D6: ='Page 17'!G4 -> 1 | E6: ='Page 17'!H4 -> 0 | F6: ='Page 17'!K4 -> AC | G6: ='Page 17'!L4 -> 0.001 | H6: ='Page 17'!N4 -> BLSR976 | I6: ='Page 17'!O4 -> 426+86.01 | J6: ='Page 17'!P4 -> 426+96.68 | K6: ='Page 17'!Q4 -> LT/RT
A43: Sub-Total: | D43: =SUBTOTAL(109,D6:D42) -> 1 | E43: =SUBTOTAL(109,E6:E42) -> 0
C45: Date:

Sheet _x0009_0110  4 10_x0009_REMOVAL OF EXIST C
A1: Final Measure : Inlet Protection System | N1: Ir al Indice
N2: Ir a Pag 17
A3: Pay Item Number | B3: Pay Item Description | C3: Units of Measure | D3: Quantity | F3: Total Quantity | H3: Location
D4: P | E4: F | F4: P | G4: F | H4: Alignment | I4: Beging Sta. | J4: End Sta. | K4: Side | L4: Description: | M4: Estimate#:
A5: Column1 | B5: Column2 | C5: Column3 | D5: Column4 | E5: Column5 | F5: Column6 | G5: Column7 | H5: Column8 | I5: Column9 | J5: Column10 | K5: Column11 | L5: Column12 | M5: Column13
A6: ='Page 17'!A5 -> 0110 4 10 | B6: ='Page 17'!B5 -> Removal Of Existing Concrete | C6: ='Page 17'!D5 -> SY | D6: ='Page 17'!G5 -> 3.2 | E6: ='Page 17'!H5 -> 0 | F6: ='Page 17'!K5 -> 0 | G6: ='Page 17'!L5 -> 0 | H6: ='Page 17'!N5 -> BLSR976 | I6: ='Page 17'!O5 -> 424+19.07 | J6: ='Page 17'!P5 -> 424+24.00 | K6: ='Page 17'!Q5 -> RT
D7: ='Page 17'!G6 -> 3.1 | E7: ='Page 17'!H6 -> 0 | F7: ='Page 17'!K6 -> 0 | G7: ='Page 17'!L6 -> 0 | H7: ='Page 17'!N6 -> BLSR976 | I7: ='Page 17'!O6 -> 424+49.76 | J7: ='Page 17'!P6 -> 424+54.69 | K7: ='Page 17'!Q6 -> LT
D8: ='Page 17'!G7 -> 3.3 | E8: ='Page 17'!H7 -> 0 | F8: ='Page 17'!K7 -> 0 | G8: ='Page 17'!L7 -> 0 | H8: ='Page 17'!N7 -> BLSR976 | I8: ='Page 17'!O7 -> 428+30.23 | J8: ='Page 17'!P7 -> 428+35.18 | K8: ='Page 17'!Q7 -> LT
A43: Sub-Total: | D43: =SUM(D6:D42) -> 9.6 | E43: =SUM(E6:E42) -> 0
C45: Date:

Sheet 0425 1451_x0009_INLETS, CURB, TYPE
A1: Final Measure : 0425 1451 INLETS, CURB, TYPE J-5, <10 | N1: Ir a Indice
N2: Ir a Pag 19
A3: Pay Item Number | B3: Pay Item Description | C3: Units of Measure | D3: Quantity | F3: Total Quantity | H3: Location
D4: P | E4: F | F4: P | G4: F | H4: Alignment | I4: Beging Sta. | J4: End Sta. | K4: Side | L4: Description: | M4: Estimate#:
A5: Column1 | B5: Column2 | C5: Column3 | D5: Column4 | E5: Column5 | F5: Column6 | G5: Column7 | H5: Column8 | I5: Column9 | J5: Column10 | K5: Column11 | L5: Column12 | M5: Column13
A6: ='Page 19'!A4 -> 0425 1451 | B6: ='Page 19'!D4 -> INLETS, CURB, TYPE J-5, <10 | C6: ='Page 19'!E4 -> EA | D6: ='Page 19'!F4 -> 1 | E6: ='Page 19'!G4 -> 0 | F6: ='Page 19'!H4 -> 1 | G6: ='Page 19'!I4 -> 0 | H6: ='Page 19'!J4 -> CL SR 976 | I6: ='Page 19'!K4 -> 418+30.33 | ... K6: ='Page 19'!M4 -> R
A43: Sub-Total: | D43: =SUBTOTAL(109,D6:D42) -> 1 | E43: =SUBTOTAL(109,E6:E42) -> 0
C45: Date:

Sheet 0425  5_x0009_MANHOLE, ADJUST 
A1: Final Measure : 14 0425 5 MANHOLE, ADJUST | N1: Ir a Indice
N2: Ir a Pag 20
A3: Pay Item Number | B3: Pay Item Description | C3: Units of Measure | D3: Quantity | F3: Total Quantity | H3: Location
D4: P | E4: F | F4: P | G4: F | H4: Alignment | I4: Beging Sta. | J4: End Sta. | K4: Side | L4: Description: | M4: Estimate#:
A5: Column1 | B5: Column2 | C5: Column3 | D5: Column4 | E5: Column5 | F5: Column6 | G5: Column7 | H5: Column8 | I5: Column9 | J5: Column10 | K5: Column11 | L5: Column12 | M5: Column13
A6: ='Page 20'!A4 -> 0425 5 | B6: ='Page 20'!B4 -> Manhole, Adjust | C6: ='Page 20'!D4 -> EA | D6: ='Page 20'!E4 -> 1 | E6: ='Page 20'!F4 -> 0 | F6: ='Page 20'!G4 -> 2 | G6: ='Page 20'!H4 -> 0 | H6: ='Page 20'!I4 -> BLSR976 | I6: ='Page 20'!J4 -> 420+47.70 | J6: ='Page 20'!K4 -> 420+47.70 | K6: ='Page 20'!L4 -> LT
D7: ='Page 20'!E5 -> 1 | E7: ='Page 20'!F5 -> 0 | F7: ='Page 20'!G5 -> 0 | G7: ='Page 20'!H5 -> 0 | H7: ='Page 20'!I5 -> BLSR976 | I7: ='Page 20'!J5 -> 426+63.63 | J7: ='Page 20'!K5 -> 426+63.63 | K7: ='Page 20'!L5 -> LT
A43: Sub-Total: | D43: =SUBTOTAL(109,D6:D42) -> 2 | E43: =SUBTOTAL(109,E6:E42) -> 0
C45: Date:

Sheet 18_x0009_0630 2 12_x0009_CONDUIT, F& I, DIR
A1: Final Measure : Inlet Protection System | N1: Ir a Indice
N2: Ir a Pag 31
A3: Pay Item Number | B3: Pay Item Description | C3: Units of Measure | D3: Quantity | F3: Total Quantity | H3: Location
D4: P | E4: F | F4: P | G4: F | H4: Alignment | I4: Beging Sta. | J4: End Sta. | K4: Side | L4: Description: | M4: Estimate#:
A5: Column1 | B5: Column2 | C5: Column3 | D5: Column4 | E5: Column5 | F5: Column6 | G5: Column7 | H5: Column8 | I5: Column9 | J5: Column10 | K5: Column11 | L5: Column12 | M5: Column13
A6: ='Page 31'!A4 -> 0630 2 12 | B6: ='Page 31'!B4 -> Conduit, Furnish & Install, Directional Bore | C6: ='Page 31'!D4 -> LF | D6: ='Page 31'!E4 -> 8.7 | E6: ='Page 31'!F4 -> 0 | F6: ='Page 31'!G4 -> 673 | G6: ='Page 31'!H4 -> 0 | H6: ='Page 31'!I4 -> BLSR976 | I6: ='Page 31'!J4 -> 421+23.03 | J6: ='Page 31'!K4 -> 421+29.64 | K6: ='Page 31'!L4 -> LT | M6: ='Page 31'!M4 -> 9426
D7: ='Page 31'!E5 -> 4.4 | E7: ='Page 31'!F5 -> 0 | F7: ='Page 31'!G5 -> 0 | G7: ='Page 31'!H5 -> 0 | H7: ='Page 31'!I5 -> BLSR976 | I7: ='Page 31'!J5 -> 421+23.06 | J7: ='Page 31'!K5 -> 421+27.38 | K7: ='Page 31'!L5 -> LT
D8: ='Page 31'!E6 -> 32.9 | E8: ='Page 31'!F6 -> 0 | F8: ='Page 31'!G6 -> 0 | G8: ='Page 31'!H6 -> 0 | H8: ='Page 31'!I6 -> BLSR976 | I8: ='Page 31'!J6 -> 421+23.06 | J8: ='Page 31'!K6 -> 421+40.82 | K8: ='Page 31'!L6 -> LT
D9: ='Page 31'!E7 -> 27.7 | E9: ='Page 31'!F7 -> 0 | F9: ='Page 31'!G7 -> 0 | G9: ='Page 31'!H7 -> 0 | H9: ='Page 31'!I7 -> BLSR976 | I9: ='Page 31'!J7 -> 421+28.85 | J9: ='Page 31'!K7 -> 421+50.41 | K9: ='Page 31'!L7 -> RT
D10: ='Page 31'!E8 -> 4.6 | E10: ='Page 31'!F8 -> 0 | F10: ='Page 31'!G8 -> 0 | G10: ='Page 31'!H8 -> 0 | H10: ='Page 31'!I8 -> BLSR976 | I10: ='Page 31'!J8 -> 421+29.38 | J10: ='Page 31'!K8 -> 421+31.55 | K10: ='Page 31'!L8 -> LT
D11: ='Page 31'!E9 -> 121.2 | E11: ='Page 31'!F9 -> 0 | F11: ='Page 31'!G9 -> 0 | G11: ='Page 31'!H9 -> 0 | H11: ='Page 31'!I9 -> BLSR976 | I11: ='Page 31'!J9 -> 421+29.71 | J11: ='Page 31'!K9 -> 422+49.09 | K11: ='Page 31'!L9 -> LT
D12: ='Page 31'!E10 -> 10.9 | E12: ='Page 31'!F10 -> 0 | F12: ='Page 31'!G10 -> 0 | G12: ='Page 31'!H10 -> 0 | H12: ='Page 31'!I10 -> BLSR976 | I12: ='Page 31'!J10 -> 421+29.90 | J12: ='Page 31'!K10 -> 421+40.63 | K12: ='Page 31'!L10 -> RT
D13: ='Page 31'!E11 -> 2.1 | E13: ='Page 31'!F11 -> 0 | F13: ='Page 31'!G11 -> 0 | G13: ='Page 31'!H11 -> 0 | H13: ='Page 31'!I11 -> BLSR976 | I13: ='Page 31'!J11 -> 421+37.25 | J13: ='Page 31'!K11 -> 421+38.32 | K13: ='Page 31'!L11 -> LT
D14: ='Page 31'!E12 -> 9.6 | E14: ='Page 31'!F12 -> 0 | F14: ='Page 31'!G12 -> 0 | G14: ='Page 31'!H12 -> 0 | H14: ='Page 31'!I12 -> BLSR976 | I14: ='Page 31'!J12 -> 421+45.70 | J14: ='Page 31'!K12 -> 421+53.08 | K14: ='Page 31'!L12 -> RT
D15: ='Page 31'!E13 -> 3.1 | E15: ='Page 31'!F13 -> 0 | F15: ='Page 31'!G13 -> 0 | G15: ='Page 31'!H13 -> 0 | H15: ='Page 31'!I13 -> BLSR976 | I15: ='Page 31'!J13 -> 421+46.74 | J15: ='Page 31'!K13 -> 421+49.44 | K15: ='Page 31'!L13 -> RT
D16: ='Page 31'!E14 -> 3 | E16: ='Page 31'!F14 -> 0 | F16: ='Page 31'!G14 -> 0 | G16: ='Page 31'!H14 -> 0 | H16: ='Page 31'!I14 -> BLSR976 | I16: ='Page 31'!J14 -> 421+47.70 | J16: ='Page 31'!K14 -> 421+49.40 | K16: ='Page 31'!L14 -> RT
D17: ='Page 31'!E15 -> 100.3 | E17: ='Page 31'!F15 -> 0 | F17: ='Page 31'!G15 -> 0 | G17: ='Page 31'!H15 -> 0 | H17: ='Page 31'!I15 -> BLSR976 | I17: ='Page 31'!J15 -> 421+52.96 | J17: ='Page 31'!K15 -> 422+47.99 | K17: ='Page 31'!L15 -> RT
D18: ='Page 31'!E16 -> 43.3 | E18: ='Page 31'!F16 -> 0 | F18: ='Page 31'!G16 -> 0 | G18: ='Page 31'!H16 -> 0 | H18: ='Page 31'!I16 -> BLSR976 | I18: ='Page 31'!J16 -> 422+25.70 | J18: ='Page 31'!K16 -> 422+49.04 | K18: ='Page 31'!L16 -> LT
... D36: ='Page 31'!E34 -> 21.1 | E36: ='Page 31'!F34 -> 0 | F36: ='Page 31'!G34 -> 0 | G36: ='Page 31'!H34 -> 0 | H36: ='Page 31'!I34 -> BLSR976 | I36: ='Page 31'!J34 -> 422+68.32 | J36: ='Page 31'!K34 -> 422+72.14 | K36: ='Page 31'!L34 -> RT
A43: Sub-Total: | D43: =SUBTOTAL(109,D6:D36) -> 673.1 | E43: =SUBTOTAL(109,E6:E36) -> 0
C45: Date:

Sheet 0632 7 1_x0009_SIGNAL CABLE- NEW O
A1: Final Measure :0632 7 1 SIGNAL CABLE- NEW OR RECO, FUR & INSTALL | N1: Ir a Indice
N2: Ir a Pag 32
A3: Pay Item Number | B3: Pay Item Description | C3: Units of Measure | D3: Quantity | F3: Total Quantity | H3: Location
D4: P | E4: F | F4: P | G4: F | H4: Alignment | I4: Beging Sta. | J4: End Sta. | K4: Side | L4: Description: | M4: Estimate#:
A5: Column1 | B5: Column2 | C5: Column3 | D5: Column4 | E5: Column5 | F5: Column6 | G5: Column7 | H5: Column8 | I5: Column9 | J5: Column10 | K5: Column11 | L5: Column12 | M5: Column13
A6: ='Page 32'!A4 -> 0632 7 1 | B6: ='Page 32'!B4 -> Signal Cable, New Or Reconstructed Intersection, Furnish & Install | C6: ='Page 32'!D4 -> PI | D6: ='Page 32'!E4 -> 1 | E6: ='Page 32'!F4 -> 0 | F6: ='Page 32'!G4 -> 1 | G6: ='Page 32'!H4 -> 0 | H6: ='Page 32'!I4 -> BLSR976 | I6: ='Page 32'!J4 -> 422+62.76 | J6: ='Page 32'!K4 -> 422+62.76 | K6: ='Page 32'!L4 -> RT
A43: Sub-Total: | D43: =SUBTOTAL(109,D6:D36) -> 1 | E43: =SUBTOTAL(109,E6:E36) -> 0
C45: Date:

Sheet 0632 7 6_x0009_SIGNAL CABLE, REMOVE- 
A1: Final Measure : 0632 7 6 SIGNAL CABLE, REMOVE- INTERSECTION | N1: Ir a Indice
N2: Ir a Pag 32
A3: Pay Item Number | B3: Pay Item Description | C3: Units of Measure | D3: Quantity | F3: Total Quantity | H3: Location
D4: P | E4: F | F4: P | G4: F | H4: Alignment | I4: Beging Sta. | J4: End Sta. | K4: Side | L4: Description: | M4: Estimate#:
A5: Column1 | B5: Column2 | C5: Column3 | D5: Column4 | E5: Column5 | F5: Column6 | G5: Column7 | H5: Column8 | I5: Column9 | J5: Column10 | K5: Column11 | L5: Column12 | M5: Column13
A6: ='Page 32'!A5 -> 0632 7 6 | B6: ='Page 32'!B5 -> Signal Cable, Remove - Intersection | C6: ='Page 32'!D5 -> PI | D6: ='Page 32'!E5 -> 1 | E6: ='Page 32'!F5 -> 0 | F6: ='Page 32'!G5 -> 1 | G6: ='Page 32'!H5 -> 0 | H6: ='Page 32'!I5 -> BLSR976 | I6: ='Page 32'!J5 -> 422+62.76 | J6: ='Page 32'!K5 -> 422+62.76 | K6: ='Page 32'!L5 -> RT
A43: Sub-Total: | D43: =SUBTOTAL(109,D6:D42) -> 1 | E43: =SUBTOTAL(109,E6:E42) -> 0
C45: Date:

Sheet 0639  1122_x0009_ELECTRICAL POWER 
A1: Final Measure : 0639 1122 ELECTRICAL POWER SERVICE, F&I, UNDERGROUND, METER PURCHASED BY CONTRACTOR | N1: Ir a Indice
N2: Ir a Pag 33
A3: Pay Item Number | B3: Pay Item Description | C3: Units of Measure | D3: Quantity | F3: Total Quantity | H3: Location
D4: P | E4: F | F4: P | G4: F | H4: Alignment | I4: Beging Sta. | J4: End Sta. | K4: Side | L4: Description: | M4: Estimate#:
A5: Column1 | B5: Column2 | C5: Column3 | D5: Column4 | E5: Column5 | F5: Column6 | G5: Column7 | H5: Column8 | I5: Column9 | J5: Column10 | K5: Column11 | L5: Column12 | M5: Column13
A6: ='Page 33'!A14 -> 0639 1122 | B6: ='Page 33'!B14 -> Electrical Power Service, F&I, Underground, Meter Furnished By Contractor | C6: ='Page 33'!D14 -> AS | D6: ='Page 33'!E14 -> 1 | E6: ='Page 33'!F14 -> 0 | F6: ='Page 33'!G14 -> 1 | G6: ='Page 33'!H14 -> 0 | H6: ='Page 33'!I14 -> BLSR976 | I6: ='Page 33'!J14 -> 422+61.44 | J6: ='Page 33'!K14 -> 422+61.44 | K6: ='Page 33'!L14 -> RT
A43: Sub-Total: | D43: =SUBTOTAL(109,D6:D40) -> 1 | E43: =SUBTOTAL(109,E6:E40) -> 0
C45: Date:

Sheet 0639 2 1_x0009_ELECTRICAL SERVICE 
A1: Final Measure : 0639 2 1 ELECTRICAL SERVICE WIRE, FURNISH & INSTALL | N1: Ir a Indice
N2: Ir a Pag 33
A3: Pay Item Number | B3: Pay Item Description | C3: Units of Measure | D3: Quantity | F3: Total Quantity | H3: Location
D4: P | E4: F | F4: P | G4: F | H4: Alignment | I4: Beging Sta. | J4: End Sta. | K4: Side | L4: Description: | M4: Estimate#:
A5: Column1 | B5: Column2 | C5: Column3 | D5: Column4 | E5: Column5 | F5: Column6 | G5: Column7 | H5: Column8 | I5: Column9 | J5: Column10 | K5: Column11 | L5: Column12 | M5: Column13
A6: ='Page 33'!A15 -> 0639 2 1 | B6: ='Page 33'!B15 -> Electrical Service Wire, Furnish & Install | C6: ='Page 33'!D15 -> LF | D6: ='Page 33'!E15 -> 118.3 | E6: ='Page 33'!F15 -> 0 | F6: ='Page 33'!G15 -> 118 | G6: ='Page 33'!H15 -> 0 | H6: ='Page 33'!I15 -> BLSR976 | I6: ='Page 33'!J15 -> 422+50.21 | J6: ='Page 33'!K15 -> 422+72.15 | K6: ='Page 33'!L15 -> LT/RT
A43: Sub-Total: | D43: =SUBTOTAL(109,D6:D40) -> 118.3 | E43: =SUBTOTAL(109,E6:E40) -> 0
C45: Date:

Sheet 0639 2 6_x0009_ELECTRICAL SERVICE 
A1: Final Measure : 0639 2 6 ELECTRICAL SERVICE WIRE, REMOVE | N1: Ir a Indice
N2: Ir a Pag 33
A3: Pay Item Number | B3: Pay Item Description | C3: Units of Measure | D3: Quantity | F3: Total Quantity | H3: Location
D4: P | E4: F | F4: P | G4: F | H4: Alignment | I4: Beging Sta. | J4: End Sta. | K4: Side | L4: Description: | M4: Estimate#:
A5: Column1 | B5: Column2 | C5: Column3 | D5: Column4 | E5: Column5 | F5: Column6 | G5: Column7 | H5: Column8 | I5: Column9 | J5: Column10 | K5: Column11 | L5: Column12 | M5: Column13
A6: ='Page 33'!A16 -> 0639 2 6 | B6: ='Page 33'!B16 -> Electrical Service Wire, Remove | C6: ='Page 33'!D16 -> LF | D6: ='Page 33'!E16 -> 90.1 | E6: ='Page 33'!F16 -> 0 | F6: ='Page 33'!G16 -> 90 | G6: ='Page 33'!H16 -> 0 | H6: ='Page 33'!I16 -> BLSR976 | I6: ='Page 33'!J16 -> 422+50.21 | J6: ='Page 33'!K16 -> 422+65.10 | K6: ='Page 33'!L16 -> LT/RT
A43: Sub-Total: | D43: =SUBTOTAL(109,D6:D40) -> 90.1 | E43: =SUBTOTAL(109,E6:E40) -> 0
C45: Date:

Sheet 0641  2 12_x0009_PREST CNC POLE,F&
A1: Final Measure : 0641 2 12 PRESTRESSED CONCRETE POLE, F&I, TYPE P-II SERVICE POLE | N1: Ir a Indice
N2: Ir a Pag 33
A3: Pay Item Number | B3: Pay Item Description | C3: Units of Measure | D3: Quantity | F3: Total Quantity | H3: Location
D4: P | E4: F | F4: P | G4: F | H4: Alignment | I4: Beging Sta. | J4: End Sta. | K4: Side | L4: Description: | M4: Estimate#:
A5: Column1 | B5: Column2 | C5: Column3 | D5: Column4 | E5: Column5 | F5: Column6 | G5: Column7 | H5: Column8 | I5: Column9 | J5: Column10 | K5: Column11 | L5: Column12 | M5: Column13
A6: ='Page 33'!A17 -> 0641 2 12 | B6: ='Page 33'!B17 -> Prestressed Concrete Pole, F&I, Type P-II Service Pole | C6: ='Page 33'!D17 -> EA | D6: ='Page 33'!E17 -> 1 | E6: ='Page 33'!F17 -> 0 | F6: ='Page 33'!G17 -> 1 | G6: ='Page 33'!H17 -> 0 | H6: ='Page 33'!I17 -> BLSR976 | I6: ='Page 33'!J17 -> 422+61.44 | J6: ='Page 33'!K17 -> 422+61.44 | K6: ='Page 33'!L17 -> RT
A43: Sub-Total: | D43: =SUBTOTAL(109,D6:D40) -> 1 | E43: =SUBTOTAL(109,E6:E40) -> 0
C45: Date:

Sheet 0641  2 60_x0009_PREST CNC POLE, R
A1: Final Measure : 0641 2 60 PRESTRESSED CONCRETE POLE, COMPLETE POLE REMOVAL- PEDESTAL/SERVICE POLE | N1: Ir a Indice
N2: Ir a Pag 33
A3: Pay Item Number | B3: Pay Item Description | C3: Units of Measure | D3: Quantity | F3: Total Quantity | H3: Location
D4: P | E4: F | F4: P | G4: F | H4: Alignment | I4: Beging Sta. | J4: End Sta. | K4: Side | L4: Description: | M4: Estimate#:
A5: Column1 | B5: Column2 | C5: Column3 | D5: Column4 | E5: Column5 | F5: Column6 | G5: Column7 | H5: Column8 | I5: Column9 | J5: Column10 | K5: Column11 | L5: Column12 | M5: Column13
A6: ='Page 33'!A18 -> 0641 2 60 | B6: ='Page 33'!B18 -> Prestressed Concrete Pole, Complete Pole Removal - Pedestal/Service Pole | C6: ='Page 33'!D18 -> EA | D6: ='Page 33'!E18 -> 1 | E6: ='Page 33'!F18 -> 0 | F6: ='Page 33'!G18 -> 1 | G6: ='Page 33'!H18 -> 0 | H6: ='Page 33'!I18 -> BLSR976 | I6: ='Page 33'!J18 -> 422+64.60 | J6: ='Page 33'!K18 -> 422+64.60 | K6: ='Page 33'!L18 -> RT
A43: Sub-Total: | D43: =SUBTOTAL(109,D6:D40) -> 1 | E43: =SUBTOTAL(109,E6:E40) -> 0
C45: Date:

Sheet 0641 2 60_x0009_PREST CNC POLE, RE
A1: Final Measure : 0641 2 60 PRESTRESSED CONCRETE POLE, COMPLETE POLE REMOVAL- PEDESTAL/SERVICE POLE | N1: Ir a Indice
N2: Ir a Pag 33
A3: Pay Item Number | B3: Pay Item Description | C3: Units of Measure | D3: Quantity | F3: Total Quantity | H3: Location
D4: P | E4: F | F4: P | G4: F | H4: Alignment | I4: Beging Sta. | J4: End Sta. | K4: Side | L4: Description: | M4: Estimate#:
A5: Column1 | B5: Column2 | C5: Column3 | D5: Column4 | E5: Column5 | F5: Column6 | G5: Column7 | H5: Column8 | I5: Column9 | J5: Column10 | K5: Column11 | L5: Column12 | M5: Column13
A6: ='Page 33'!A18 -> 0641 2 60 | B6: ='Page 33'!B18 -> Prestressed Concrete Pole, Complete Pole Removal - Pedestal/Service Pole | C6: ='Page 33'!D18 -> EA | D6: ='Page 33'!E18 -> 1 | E6: ='Page 33'!F18 -> 0 | F6: ='Page 33'!G18 -> 1 | G6: ='Page 33'!H18 -> 0 | H6: ='Page 33'!I18 -> BLSR976 | I6: ='Page 33'!J18 -> 422+64.60 | J6: ='Page 33'!K18 -> 422+64.60 | K6: ='Page 33'!L18 -> RT
A43: Sub-Total: | D43: =SUBTOTAL(109,D6:D42) -> 1 | E43: =SUBTOTAL(109,E6:E42) -> 0
C45: Date:

Sheet 0646  1 11_x0009_ALUMINUM SIGNALS 
A1: Final Measure : 0646 1 11 ALUMINUM SIGNALS POLE, PEDESTAL | N1: Ir a Indice
N2: Ir a Pag 33
A3: Pay Item Number | B3: Pay Item Description | C3: Units of Measure | D3: Quantity | F3: Total Quantity | H3: Location
D4: P | E4: F | F4: P | G4: F | H4: Alignment | I4: Beging Sta. | J4: End Sta. | K4: Side | L4: Description: | M4: Estimate#:
A5: Column1 | B5: Column2 | C5: Column3 | D5: Column4 | E5: Column5 | F5: Column6 | G5: Column7 | H5: Column8 | I5: Column9 | J5: Column10 | K5: Column11 | L5: Column12 | M5: Column13
A6: ='Page 33'!A19 -> 0646 1 11 | B6: ='Page 33'!B19 -> Aluminum Signals Pole, Furnish & Install, Pedestal | C6: ='Page 33'!D19 -> EA | D6: ='Page 33'!E19 -> 1 | E6: ='Page 33'!F19 -> 0 | F6: ='Page 33'!G19 -> 8 | G6: ='Page 33'!H19 -> 0 | H6: ='Page 33'!I19 -> BLSR976 | I6: ='Page 33'!J19 -> 421+27.31 | J6: ='Page 33'!K19 -> 421+27.31 | K6: ='Page 33'!L19 -> LT
D7: ='Page 33'!E20 -> 1 | E7: ='Page 33'!F20 -> 0 | F7: ='Page 33'!G20 -> 0 | G7: ='Page 33'!H20 -> 0 | H7: ='Page 33'!I20 -> BLSR976 | I7: ='Page 33'!J20 -> 421+38.34 | J7: ='Page 33'!K20 -> 421+38.34 | K7: ='Page 33'!L20 -> LT
D8: ='Page 33'!E21 -> 1 | E8: ='Page 33'!F21 -> 0 | F8: ='Page 33'!G21 -> 0 | G8: ='Page 33'!H21 -> 0 | H8: ='Page 33'!I21 -> BLSR976 | I8: ='Page 33'!J21 -> 421+40.71 | J8: ='Page 33'!K21 -> 421+40.71 | K8: ='Page 33'!L21 -> RT
D9: ='Page 33'!E22 -> 1 | E9: ='Page 33'!F22 -> 0 | F9: ='Page 33'!G22 -> 0 | G9: ='Page 33'!H22 -> 0 | H9: ='Page 33'!I22 -> BLSR976 | I9: ='Page 33'!J22 -> 421+47.65 | J9: ='Page 33'!K22 -> 421+47.65 | K9: ='Page 33'!L22 -> RT
D10: ='Page 33'!E23 -> 1 | E10: ='Page 33'!F23 -> 0 | F10: ='Page 33'!G23 -> 0 | G10: ='Page 33'!H23 -> 0 | H10: ='Page 33'!I23 -> BLSR976 | I10: ='Page 33'!J23 -> 422+31.04 | J10: ='Page 33'!K23 -> 422+31.04 | K10: ='Page 33'!L23 -> RT
D11: ='Page 33'!E24 -> 1 | E11: ='Page 33'!F24 -> 0 | F11: ='Page 33'!G24 -> 0 | G11: ='Page 33'!H24 -> 0 | H11: ='Page 33'!I24 -> BLSR976 | I11: ='Page 33'!J24 -> 422+32.86 | J11: ='Page 33'!K24 -> 422+32.86 | K11: ='Page 33'!L24 -> RT
D12: ='Page 33'!E25 -> 1 | E12: ='Page 33'!F25 -> 0 | F12: ='Page 33'!G25 -> 0 | G12: ='Page 33'!H25 -> 0 | H12: ='Page 33'!I25 -> BLSR976 | I12: ='Page 33'!J25 -> 422+34.64 | J12: ='Page 33'!K25 -> 422+34.64 | K12: ='Page 33'!L25 -> LT
D13: ='Page 33'!E26 -> 1 | E13: ='Page 33'!F26 -> 0 | F13: ='Page 33'!G26 -> 0 | G13: ='Page 33'!H26 -> 0 | H13: ='Page 33'!I26 -> BLSR976 | I13: ='Page 33'!J26 -> 422+40.57 | J13: ='Page 33'!K26 -> 422+40.57 | K13: ='Page 33'!L26 -> LT
A43: Sub-Total: | D43: =SUBTOTAL(109,D6:D42) -> 8 | E43: =SUBTOTAL(109,E6:E42) -> 0
C45: Date:

Sheet 0646  1 60_x0009_ALUMINUM SIGNALS 
A1: Final Measure : 0646 1 60 ALUMINUM SIGNALS POLE, REMOVE | N1: Ir a Indice
N2: Ir a Pag 33
A3: Pay Item Number | B3: Pay Item Description | C3: Units of Measure | D3: Quantity | F3: Total Quantity | H3: Location
D4: P | E4: F | F4: P | G4: F | H4: Alignment | I4: Beging Sta. | J4: End Sta. | K4: Side | L4: Description: | M4: Estimate#:
A5: Column1 | B5: Column2 | C5: Column3 | D5: Column4 | E5: Column5 | F5: Column6 | G5: Column7 | H5: Column8 | I5: Column9 | J5: Column10 | K5: Column11 | L5: Column12 | M5: Column13
A6: ='Page 33'!A27 -> 0646 1 60 | B6: ='Page 33'!B27 -> Aluminum Signals Pole, Remove | C6: ='Page 33'!D27 -> EA | D6: ='Page 33'!E27 -> 1 | E6: ='Page 33'!F27 -> 0 | F6: ='Page 33'!G27 -> 4 | G6: ='Page 33'!H27 -> 0 | H6: ='Page 33'!I27 -> BLSR976 | I6: ='Page 33'!J27 -> 421+32.37 | J6: ='Page 33'!K27 -> 421+32.37 | K6: ='Page 33'!L27 -> RT
C7: ='Page 33'!D28 -> 0 | D7: ='Page 33'!E28 -> 1 | E7: ='Page 33'!F28 -> 0 | F7: ='Page 33'!G28 -> 0 | G7: ='Page 33'!H28 -> 0 | H7: ='Page 33'!I28 -> BLSR976 | I7: ='Page 33'!J28 -> 421+37.66 | J7: ='Page 33'!K28 -> 421+37.66 | K7: ='Page 33'!L28 -> LT
C8: ='Page 33'!D29 -> 0 | D8: ='Page 33'!E29 -> 1 | E8: ='Page 33'!F29 -> 0 | F8: ='Page 33'!G29 -> 0 | G8: ='Page 33'!H29 -> 0 | H8: ='Page 33'!I29 -> BLSR976 | I8: ='Page 33'!J29 -> 422+29.40 | J8: ='Page 33'!K29 -> 422+29.40 | K8: ='Page 33'!L29 -> RT
C9: ='Page 33'!D30 -> 0 | D9: ='Page 33'!E30 -> 1 | E9: ='Page 33'!F30 -> 0 | F9: ='Page 33'!G30 -> 0 | G9: ='Page 33'!H30 -> 0 | H9: ='Page 33'!I30 -> BLSR976 | I9: ='Page 33'!J30 -> 422+39.74 | J9: ='Page 33'!K30 -> 422+39.74 | K9: ='Page 33'!L30 -> LT
A34: Sub-Total: | D34: =SUBTOTAL(109,D6:D31) -> 4 | E34: =SUBTOTAL(109,E6:E31) -> 0
C36: Date:

Sheet 0653  1 11_x0009_PEDESTRIAN SIGNAL
A1: Final Measure : 0653 1 11 PEDESTRIAN SIGNAL, FURNISH & INSTALL LED COUNTDOWN, 1 WAY | N1: Ir a Indice
N2: Ir a Pag 33
A3: Pay Item Number | B3: Pay Item Description | C3: Units of Measure | D3: Quantity | F3: Total Quantity | H3: Location
D4: P | E4: F | F4: P | G4: F | H4: Alignment | I4: Beging Sta. | J4: End Sta. | K4: Side | L4: Description: | M4: Estimate#:
A5: Column1 | B5: Column2 | C5: Column3 | D5: Column4 | E5: Column5 | F5: Column6 | G5: Column7 | H5: Column8 | I5: Column9 | J5: Column10 | K5: Column11 | L5: Column12 | M5: Column13
A6: ='Page 33'!A31 -> 0653 1 11 | B6: ='Page 33'!B31 -> Pedestrian Signal, Furnish & Install Led Countdown, 1 Way | C6: ='Page 33'!D31 -> AS | D6: ='Page 33'!E31 -> 1 | E6: ='Page 33'!F31 -> 0 | F6: ='Page 33'!G31 -> 8 | G6: ='Page 33'!H31 -> 0 | H6: ='Page 33'!I31 -> BLSR976 | I6: ='Page 33'!J31 -> 421+27.31 | J6: ='Page 33'!K31 -> 421+27.31 | K6: ='Page 33'!L31 -> LT
C7: ='Page 33'!D32 -> 0 | D7: ='Page 33'!E32 -> 1 | E7: ='Page 33'!F32 -> 0 | F7: ='Page 33'!G32 -> 0 | G7: ='Page 33'!H32 -> 0 | H7: ='Page 33'!I32 -> BLSR976 | I7: ='Page 33'!J32 -> 421+38.32 | J7: ='Page 33'!K32 -> 421+38.32 | K7: ='Page 33'!L32 -> LT
C8: ='Page 33'!D33 -> 0 | D8: ='Page 33'!E33 -> 1 | E8: ='Page 33'!F33 -> 0 | F8: ='Page 33'!G33 -> 0 | G8: ='Page 33'!H33 -> 0 | H8: ='Page 33'!I33 -> BLSR976 | I8: ='Page 33'!J33 -> 421+40.71 | J8: ='Page 33'!K33 -> 421+40.71 | K8: ='Page 33'!L33 -> RT
C9: ='Page 34'!D4 -> 0 | D9: ='Page 34'!E4 -> 1 | E9: ='Page 34'!F4 -> 0 | F9: ='Page 34'!G4 -> 0 | G9: ='Page 34'!H4 -> 0 | H9: ='Page 34'!I4 -> BLSR976 | I9: ='Page 34'!J4 -> 421+47.65 | J9: ='Page 34'!K4 -> 421+47.65 | K9: ='Page 34'!L4 -> RT
C10: ='Page 34'!D5 -> 0 | D10: ='Page 34'!E5 -> 1 | E10: ='Page 34'!F5 -> 0 | F10: ='Page 34'!G5 -> 0 | G10: ='Page 34'!H5 -> 0 | H10: ='Page 34'!I5 -> BLSR976 | I10: ='Page 34'!J5 -> 422+31.04 | J10: ='Page 34'!K5 -> 422+31.04 | K10: ='Page 34'!L5 -> RT
C11: ='Page 34'!D6 -> 0 | D11: ='Page 34'!E6 -> 1 | E11: ='Page 34'!F6 -> 0 | F11: ='Page 34'!G6 -> 0 | G11: ='Page 34'!H6 -> 0 | H11: ='Page 34'!I6 -> BLSR976 | I11: ='Page 34'!J6 -> 422+32.86 | J11: ='Page 34'!K6 -> 422+32.86 | K11: ='Page 34'!L6 -> RT
C12: ='Page 34'!D7 -> 0 | D12: ='Page 34'!E7 -> 1 | E12: ='Page 34'!F7 -> 0 | F12: ='Page 34'!G7 -> 0 | G12: ='Page 34'!H7 -> 0 | H12: ='Page 34'!I7 -> BLSR976 | I12: ='Page 34'!J7 -> 422+34.64 | J12: ='Page 34'!K7 -> 422+34.64 | K12: ='Page 34'!L7 -> LT
C13: ='Page 34'!D8 -> 0 | D13: ='Page 34'!E8 -> 1 | E13: ='Page 34'!F8 -> 0 | F13: ='Page 34'!G8 -> 0 | G13: ='Page 34'!H8 -> 0 | H13: ='Page 34'!I8 -> BLSR976 | I13: ='Page 34'!J8 -> 422+40.57 | J13: ='Page 34'!K8 -> 422+40.57 | K13: ='Page 34'!L8 -> LT
A34: Sub-Total: | D34: =SUBTOTAL(109,D6:D31) -> 8 | E34: =SUBTOTAL(109,E6:E31) -> 0
C36: Date:

Sheet 0653  1 60_x0009_PEDESTRIAN SIGNAL
A1: Final Measure : 0653 1 60 PEDESTRIAN SIGNAL | N1: Ir a Indice
N2: Ir a Pag 34
A3: Pay Item Number | B3: Pay Item Description | C3: Units of Measure | D3: Quantity | F3: Total Quantity | H3: Location
D4: P | E4: F | F4: P | G4: F | H4: Alignment | I4: Beging Sta. | J4: End Sta. | K4: Side | L4: Description: | M4: Estimate#:
A5: Column1 | B5: Column2 | C5: Column3 | D5: Column4 | E5: Column5 | F5: Column6 | G5: Column7 | H5: Column8 | I5: Column9 | J5: Column10 | K5: Column11 | L5: Column12 | M5: Column13
A6: ='Page 34'!A9 -> 0653 1 60 | B6: ='Page 34'!B9 -> Pedestrian Signal, Remove Ped Signal- Pole/Pedestal To Remain | C6: ='Page 34'!D9 -> AS | D6: ='Page 34'!E9 -> 1 | E6: ='Page 34'!F9 -> 0 | F6: ='Page 34'!G9 -> 4 | G6: ='Page 34'!H9 -> 0 | H6: ='Page 34'!I9 -> BLSR976 | I6: ='Page 34'!J9 -> 421+30.58 | J6: ='Page 34'!K9 -> 421+30.58 | K6: ='Page 34'!L9 -> LT
D7: ='Page 34'!E10 -> 1 | E7: ='Page 34'!F10 -> 0 | F7: ='Page 34'!G10 -> 0 | G7: ='Page 34'!H10 -> 0 | H7: ='Page 34'!I10 -> BLSR976 | I7: ='Page 34'!J10 -> 421+47.89 | J7: ='Page 34'!K10 -> 421+47.89 | K7: ='Page 34'!L10 -> RT
D8: ='Page 34'!E11 -> 1 | E8: ='Page 34'!F11 -> 0 | F8: ='Page 34'!G11 -> 0 | G8: ='Page 34'!H11 -> 0 | H8: ='Page 34'!I11 -> BLSR976 | I8: ='Page 34'!J11 -> 422+32.73 | J8: ='Page 34'!K11 -> 422+32.73 | K8: ='Page 34'!L11 -> LT
D9: ='Page 34'!E12 -> 1 | E9: ='Page 34'!F12 -> 0 | F9: ='Page 34'!G12 -> 0 | G9: ='Page 34'!H12 -> 0 | H9: ='Page 34'!I12 -> BLSR976 | I9: ='Page 34'!J12 -> 422+41.68 | J9: ='Page 34'!K12 -> 422+41.68 | K9: ='Page 34'!L12 -> RT
A43: Sub-Total: | D43: =SUBTOTAL(109,D6:D42) -> 4 | E43: =SUBTOTAL(109,E6:E42) -> 0
C45: Date:

Sheet 0660 4 11_x0009_VEHICLE DETECTION 
A1: Final Measure : 0660 4 11 Vehicle Detection System - Video, Furnish & Install, Cabinet Equipment | N1: Ir a Indice
N2: Ir a Pag 34
A3: Pay Item Number | B3: Pay Item Description | C3: Units of Measure | D3: Quantity | F3: Total Quantity | H3: Location
D4: P | E4: F | F4: P | G4: F | H4: Alignment | I4: Beging Sta. | J4: End Sta. | K4: Side | L4: Description: | M4: Estimate#:
A5: Column1 | B5: Column2 | C5: Column3 | D5: Column4 | E5: Column5 | F5: Column6 | G5: Column7 | H5: Column8 | I5: Column9 | J5: Column10 | K5: Column11 | L5: Column12 | M5: Column13
A6: ='Page 34'!A13 -> 0660 4 11 | B6: ='Page 34'!B13 -> Vehicle Detection System - Video, Furnish & Install, Cabinet Equipment | C6: ='Page 34'!D13 -> EA | D6: ='Page 34'!E13 -> 4 | E6: ='Page 34'!F13 -> 0 | F6: ='Page 34'!G13 -> 4 | G6: ='Page 34'!H13 -> 0 | H6: ='Page 34'!I13 -> BLSR976 | I6: ='Page 34'!J13 -> 422+62.76 | J6: ='Page 34'!K13 -> 422+62.76 | K6: ='Page 34'!L13 -> RT
A43: Sub-Total: | D43: =SUBTOTAL(109,D6:D42) -> 4 | E43: =SUBTOTAL(109,E6:E42) -> 0
C45: Date:

Sheet 0660 4 12_x0009_VEHICLE DETECTION SYS
A1: Final Measure :0660 4 12Vehicle Detection System - Video, Furnish & Install, Above | N1: Ir a Indice
N2: Ir a Pag 34
A3: Pay Item Number | B3: Pay Item Description | C3: Units of Measure | D3: Quantity | F3: Total Quantity | H3: Location
D4: P | E4: F | F4: P | G4: F | H4: Alignment | I4: Beging Sta. | J4: End Sta. | K4: Side | L4: Description: | M4: Estimate#:
A5: Column1 | B5: Column2 | C5: Column3 | D5: Column4 | E5: Column5 | F5: Column6 | G5: Column7 | H5: Column8 | I5: Column9 | J5: Column10 | K5: Column11 | L5: Column12 | M5: Column13
A6: ='Page 34'!A14 -> 0660 4 12 | B6: ='Page 34'!B14 -> Vehicle Detection System - Video, Furnish & Install, Above Ground Equipment | C6: ='Page 34'!D14 -> EA | D6: ='Page 34'!E14 -> 1 | E6: ='Page 34'!F14 -> 0 | F6: ='Page 34'!G14 -> 4 | G6: ='Page 34'!H14 -> 0 | H6: ='Page 34'!I14 -> BLSR976 | I6: ='Page 34'!J14 -> 421+32.63 | J6: ='Page 34'!K14 -> 421+32.63 | K6: ='Page 34'!L14 -> LT
D7: ='Page 34'!E15 -> 1 | E7: ='Page 34'!F15 -> 0 | F7: ='Page 34'!G15 -> 0 | G7: ='Page 34'!H15 -> 0 | H7: ='Page 34'!I15 -> BLSR976 | I7: ='Page 34'!J15 -> 421+88.58 | J7: ='Page 34'!K15 -> 421+88.58 | K7: ='Page 34'!L15 -> RT
D8: ='Page 34'!E16 -> 1 | E8: ='Page 34'!F16 -> 0 | F8: ='Page 34'!G16 -> 0 | G8: ='Page 34'!H16 -> 0 | H8: ='Page 34'!I16 -> BLSR976 | I8: ='Page 34'!J16 -> 421+99.00 | J8: ='Page 34'!K16 -> 421+99.00 | K8: ='Page 34'!L16 -> LT
D9: ='Page 34'!E17 -> 1 | E9: ='Page 34'!F17 -> 0 | F9: ='Page 34'!G17 -> 0 | G9: ='Page 34'!H17 -> 0 | H9: ='Page 34'!I17 -> BLSR976 | I9: ='Page 34'!J17 -> 422+42.41 | J9: ='Page 34'!K17 -> 422+42.41 | K9: ='Page 34'!L17 -> RT
A43: Sub-Total: | D43: =SUBTOTAL(109,D6:D42) -> 4 | E43: =SUBTOTAL(109,E6:E42) -> 0
C45: Date:

Sheet 0665 1 12_x0009_PEDESTRIAN DETECTOR, 
A1: Final Measure : 0665 1 12 PEDESTRIAN DETECTOR, FURNISH & INSTALL, ACCESSIBLE | N1: Ir a Indice
N2: Ir a Pag 34
A3: Pay Item Number | B3: Pay Item Description | C3: Units of Measure | D3: Quantity | F3: Total Quantity | H3: Location
D4: P | E4: F | F4: P | G4: F | H4: Alignment | I4: Beging Sta. | J4: End Sta. | K4: Side | L4: Description: | M4: Estimate#:
A5: Column1 | B5: Column2 | C5: Column3 | D5: Column4 | E5: Column5 | F5: Column6 | G5: Column7 | H5: Column8 | I5: Column9 | J5: Column10 | K5: Column11 | L5: Column12 | M5: Column13
A6: ='Page 34'!A18 -> 0665 1 12 | B6: ='Page 34'!B18 -> Pedestrian Detector, Furnish & Install, Accessible | C6: ='Page 34'!D18 -> EA | D6: ='Page 34'!E18 -> 1 | E6: ='Page 34'!F18 -> 0 | F6: ='Page 34'!G18 -> 8 | G6: ='Page 34'!H18 -> 0 | H6: ='Page 34'!I18 -> BLSR976 | I6: ='Page 34'!J18 -> 421+27.31 | J6: ='Page 34'!K18 -> 421+27.31 | K6: ='Page 34'!L18 -> LT
D7: ='Page 34'!E19 -> 1 | E7: ='Page 34'!F19 -> 0 | F7: ='Page 34'!G19 -> 0 | G7: ='Page 34'!H19 -> 0 | H7: ='Page 34'!I19 -> BLSR976 | I7: ='Page 34'!J19 -> 421+38.34 | J7: ='Page 34'!K19 -> 421+38.34 | K7: ='Page 34'!L19 -> LT
D8: ='Page 34'!E20 -> 1 | E8: ='Page 34'!F20 -> 0 | F8: ='Page 34'!G20 -> 0 | G8: ='Page 34'!H20 -> 0 | H8: ='Page 34'!I20 -> BLSR976 | I8: ='Page 34'!J20 -> 421+40.71 | J8: ='Page 34'!K20 -> 421+40.71 | K8: ='Page 34'!L20 -> RT
D9: ='Page 34'!E21 -> 1 | E9: ='Page 34'!F21 -> 0 | F9: ='Page 34'!G21 -> 0 | G9: ='Page 34'!H21 -> 0 | H9: ='Page 34'!I21 -> BLSR976 | I9: ='Page 34'!J21 -> 421+47.65 | J9: ='Page 34'!K21 -> 421+47.65 | K9: ='Page 34'!L21 -> RT
D10: ='Page 34'!E22 -> 1 | E10: ='Page 34'!F22 -> 0 | F10: ='Page 34'!G22 -> 0 | G10: ='Page 34'!H22 -> 0 | H10: ='Page 34'!I22 -> BLSR976 | I10: ='Page 34'!J22 -> 422+31.04 | J10: ='Page 34'!K22 -> 422+31.04 | K10: ='Page 34'!L22 -> RT
D11: ='Page 34'!E23 -> 1 | E11: ='Page 34'!F23 -> 0 | F11: ='Page 34'!G23 -> 0 | G11: ='Page 34'!H23 -> 0 | H11: ='Page 34'!I23 -> BLSR976 | I11: ='Page 34'!J23 -> 422+32.86 | J11: ='Page 34'!K23 -> 422+32.86 | K11: ='Page 34'!L23 -> RT
D12: ='Page 34'!E24 -> 1 | E12: ='Page 34'!F24 -> 0 | F12: ='Page 34'!G24 -> 0 | G12: ='Page 34'!H24 -> 0 | H12: ='Page 34'!I24 -> BLSR976 | I12: ='Page 34'!J24 -> 422+34.64 | J12: ='Page 34'!K24 -> 422+34.64 | K12: ='Page 34'!L24 -> LT
D13: ='Page 34'!E25 -> 1 | E13: ='Page 34'!F25 -> 0 | F13: ='Page 34'!G25 -> 0 | G13: ='Page 34'!H25 -> 0 | H13: ='Page 34'!I25 -> BLSR976 | I13: ='Page 34'!J25 -> 422+40.57 | J13: ='Page 34'!K25 -> 422+40.57 | K13: ='Page 34'!L25 -> LT
A43: Sub-Total: | D43: =SUBTOTAL(109,D6:D39) -> 8 | E43: =SUBTOTAL(109,E6:E39) -> 0
C45: Date:

Sheet 0665 1 60_x0009_PEDESTRIAN DETECTO
A1: Final Measure : 0665 1 60 PEDESTRIAN DETECTOR, REMOVE- POLE/PEDESTAL TO REMAIN | N1: Ir a Indice
N2: Ir a Pag 34
A3: Pay Item Number | B3: Pay Item Description | C3: Units of Measure | D3: Quantity | F3: Total Quantity | H3: Location
D4: P | E4: F | F4: P | G4: F | H4: Alignment | I4: Beging Sta. | J4: End Sta. | K4: Side | L4: Description: | M4: Estimate#:
A5: Column1 | B5: Column2 | C5: Column3 | D5: Column4 | E5: Column5 | F5: Column6 | G5: Column7 | H5: Column8 | I5: Column9 | J5: Column10 | K5: Column11 | L5: Column12 | M5: Column13
A6: ='Page 34'!A26 -> 0665 1 60 | B6: ='Page 34'!B26 -> Pedestrian Detector, Remove - Pole/Pedestal To Remain | C6: ='Page 34'!D26 -> EA | D6: ='Page 34'!E26 -> 1 | E6: ='Page 34'!F26 -> 0 | F6: ='Page 34'!G26 -> 2 | G6: ='Page 34'!H26 -> 0 | H6: ='Page 34'!I26 -> BLSR976 | I6: ='Page 34'!J26 -> 421+30.58 | J6: ='Page 34'!K26 -> 421+30.58 | K6: ='Page 34'!L26 -> LT
C7: ='Page 34'!D27 -> 0 | D7: ='Page 34'!E27 -> 1 | E7: ='Page 34'!F27 -> 0 | F7: ='Page 34'!G27 -> 0 | G7: ='Page 34'!H27 -> 0 | H7: ='Page 34'!I27 -> BLSR976 | I7: ='Page 34'!J27 -> 422+41.68 | J7: ='Page 34'!K27 -> 422+41.68 | K7: ='Page 34'!L27 -> RT
A43: Sub-Total: | D43: =SUBTOTAL(109,D6:D39) -> 2 | E43: =SUBTOTAL(109,E6:E39) -> 0
C45: Date:

Sheet 0670 5140_x0009_TRAF CNTL ASSEM, F&I,
A1: Final Measure : 0670 5140 TRAF CNTL ASSEM, F&I, MODEL 2070 | N1: Ir a Indice
N2: Ir a Pag 34
A3: Pay Item Number | B3: Pay Item Description | C3: Units of Measure | D3: Quantity | F3: Total Quantity | H3: Location
D4: P | E4: F | F4: P | G4: F | H4: Alignment | I4: Beging Sta. | J4: End Sta. | K4: Side | L4: Description: | M4: Estimate#:
A5: Column1 | B5: Column2 | C5: Column3 | D5: Column4 | E5: Column5 | F5: Column6 | G5: Column7 | H5: Column8 | I5: Column9 | J5: Column10 | K5: Column11 | L5: Column12 | M5: Column13
A6: ='Page 34'!A28 -> 0670 5140 | B6: ='Page 34'!B28 -> Traffic Controller Assembly, F&I, Model 2070 | C6: ='Page 34'!D28 -> AS | D6: ='Page 34'!E28 -> 1 | E6: ='Page 34'!F28 -> 0 | F6: ='Page 34'!G28 -> 1 | G6: ='Page 34'!H28 -> 0 | H6: ='Page 34'!I28 -> BLSR976 | I6: ='Page 34'!J28 -> 422+62.76 | J6: ='Page 34'!K28 -> 422+62.76 | K6: ='Page 34'!L28 -> RT
A43: Sub-Total: | D43: =SUBTOTAL(109,D6:D42) -> 1 | E43: =SUBTOTAL(109,E6:E42) -> 0
C45: Date:

Sheet 0670 5600_x0009_TRAF CNTL ASSEM, R
A1: Final Measure : 0670 5600 TRAFFIC CONTROLLER ASSEMBLY, REMOVE CONTROLLER WITH CABINET | N1: Ir a Indice
N2: Ir a Pag 34
A3: Pay Item Number | B3: Pay Item Description | C3: Units of Measure | D3: Quantity | F3: Total Quantity | H3: Location
D4: P | E4: F | F4: P | G4: F | H4: Alignment | I4: Beging Sta. | J4: End Sta. | K4: Side | L4: Description: | M4: Estimate#:
A5: Column1 | B5: Column2 | C5: Column3 | D5: Column4 | E5: Column5 | F5: Column6 | G5: Column7 | H5: Column8 | I5: Column9 | J5: Column10 | K5: Column11 | L5: Column12 | M5: Column13
A6: ='Page 34'!A29 -> 0670 5600 | B6: ='Page 34'!B29 -> Traffic Controller Assembly, Remove, Controller And Cabinet | C6: ='Page 34'!D29 -> AS | D6: ='Page 34'!E29 -> 1 | E6: ='Page 34'!F29 -> 0 | F6: ='Page 34'!G29 -> 1 | G6: ='Page 34'!H29 -> 0 | H6: ='Page 34'!I29 -> BLSR976 | I6: ='Page 34'!J29 -> 422+50.44 | J6: ='Page 34'!K29 -> 422+50.44 | K6: ='Page 34'!L29 -> RT
A43: Sub-Total: | D43: =SUBTOTAL(109,D6:D42) -> 1 | E43: =SUBTOTAL(109,E6:E42) -> 0
C45: Date:

Sheet 0684 90102_x0009_NET DEV, CELLULAR
A1: Final Measure : 0684 90102 NET DEV, CELLULAR MODEM | N1: Ir a Indice
N2: Ir a Pag 34
A3: Pay Item Number | B3: Pay Item Description | C3: Units of Measure | D3: Quantity | F3: Total Quantity | H3: Location
D4: P | E4: F | F4: P | G4: F | H4: Alignment | I4: Beging Sta. | J4: End Sta. | K4: Side | L4: Description: | M4: Estimate#:
A5: Column1 | B5: Column2 | C5: Column3 | D5: Column4 | E5: Column5 | F5: Column6 | G5: Column7 | H5: Column8 | I5: Column9 | J5: Column10 | K5: Column11 | L5: Column12 | M5: Column13
A6: ='Page 34'!A30 -> 0684 90102 | B6: ='Page 34'!B30 -> Network Device, Cellular Modem | C6: ='Page 34'!D30 -> EA | D6: ='Page 34'!E30 -> 1 | E6: ='Page 34'!F30 -> 0 | F6: ='Page 34'!G30 -> 1 | G6: ='Page 34'!H30 -> 0 | H6: ='Page 34'!I30 -> BLSR976 | I6: ='Page 34'!J30 -> 422+62.76 | J6: ='Page 34'!K30 -> 422+62.76 | K6: ='Page 34'!L30 -> RT
A43: Sub-Total: | D43: =SUBTOTAL(109,D6:D42) -> 1 | E43: =SUBTOTAL(109,E6:E42) -> 0
C45: Date:

Sheet 0650 1 14_x0009_VEHICULAR TRAFFIC SIG
A1: Final Measure : 0650 1 14 VEHICULAR TRAFFIC SIGNAL, FURNISH & INSTALL ALUMINIUM, 3 SECTION, 1 WAY | N1: Ir a Indice
N2: Ir a Pag 36
A3: Pay Item Number | B3: Pay Item Description | C3: Units of Measure | D3: Quantity | F3: Total Quantity | H3: Location
D4: P | E4: F | F4: P | G4: F | H4: Alignment | I4: Beging Sta. | J4: End Sta. | K4: Side | L4: Description: | M4: Estimate#:
A5: Column1 | B5: Column2 | C5: Column3 | D5: Column4 | E5: Column5 | F5: Column6 | G5: Column7 | H5: Column8 | I5: Column9 | J5: Column10 | K5: Column11 | L5: Column12 | M5: Column13
A6: ='Page 36'!A4 -> 0650 1 14 | B6: ='Page 36'!B4 -> Vehicular Traffic Signal, Furnish & Install Aluminum, 3 Section, 1 Way | C6: ='Page 36'!D4 -> AS | D6: ='Page 36'!E4 -> 1 | E6: ='Page 36'!F4 -> 0 | F6: ='Page 36'!G4 -> 3 | G6: ='Page 36'!H4 -> 0 | H6: ='Page 36'!I4 -> BLSR976 | I6: ='Page 36'!J4 -> 421+31.97 | J6: ='Page 36'!K4 -> 421+31.97 | K6: ='Page 36'!L4 -> LT
D7: ='Page 36'!E5 -> 1 | E7: ='Page 36'!F5 -> 0 | F7: ='Page 36'!G5 -> 0 | G7: ='Page 36'!H5 -> 0 | H7: ='Page 36'!I5 -> BLSR976 | I7: ='Page 36'!J5 -> 422+10.06 | J7: ='Page 36'!K5 -> 422+10.06 | K7: ='Page 36'!L5 -> LT
D8: ='Page 36'!E6 -> 1 | E8: ='Page 36'!F6 -> 0 | F8: ='Page 36'!G6 -> 0 | G8: ='Page 36'!H6 -> 0 | H8: ='Page 36'!I6 -> BLSR976 | I8: ='Page 36'!J6 -> 422+42.04 | J8: ='Page 36'!K6 -> 422+42.04 | K8: ='Page 36'!L6 -> RT
A43: Sub-Total: | D43: =SUBTOTAL(109,D6:D42) -> 3 | E43: =SUBTOTAL(109,E6:E42) -> 0
C45: Date:

Sheet 0650 1 18_x0009_VEHICULAR TRAFFIC SIG
A1: Final Measure : 0650 1 18 VEHICULAR TRAFFIC SIGNAL, FURNISH & INSTALL ALUMINIUM, 5 SECTION STRAIGHT, 1 WAY | N1: Ir a Indice
N2: Ir a Pag 36
A3: Pay Item Number | B3: Pay Item Description | C3: Units of Measure | D3: Quantity | F3: Total Quantity | H3: Location
D4: P | E4: F | F4: P | G4: F | H4: Alignment | I4: Beging Sta. | J4: End Sta. | K4: Side | L4: Description: | M4: Estimate#:
A5: Column1 | B5: Column2 | C5: Column3 | D5: Column4 | E5: Column5 | F5: Column6 | G5: Column7 | H5: Column8 | I5: Column9 | J5: Column10 | K5: Column11 | L5: Column12 | M5: Column13
A6: ='Page 36'!A7 -> 0650 1 18 | B6: ='Page 36'!B7 -> Vehicular Traffic Signal, Furnish & Install Aluminum, 5 Section Straight, 1 Way | C6: ='Page 36'!D7 -> AS | D6: ='Page 36'!E7 -> 1 | E6: ='Page 36'!F7 -> 0 | F6: ='Page 36'!G7 -> 6 | G6: ='Page 36'!H7 -> 0 | H6: ='Page 36'!I7 -> BLSR976 | I6: ='Page 36'!J7 -> 421+32.72 | J6: ='Page 36'!K7 -> 421+32.72 | K6: ='Page 36'!L7 -> RT
D7: ='Page 36'!E8 -> 1 | E7: ='Page 36'!F8 -> 0 | F7: ='Page 36'!G8 -> 0 | G7: ='Page 36'!H8 -> 0 | H7: ='Page 36'!I8 -> BLSR976 | I7: ='Page 36'!J8 -> 421+67.52 | J7: ='Page 36'!K8 -> 421+67.52 | K7: ='Page 36'!L8 -> RT
D8: ='Page 36'!E9 -> 1 | E8: ='Page 36'!F9 -> 0 | F8: ='Page 36'!G9 -> 0 | G8: ='Page 36'!H9 -> 0 | H8: ='Page 36'!I9 -> BLSR976 | I8: ='Page 36'!J9 -> 421+87.10 | J8: ='Page 36'!K9 -> 421+87.10 | K8: ='Page 36'!L9 -> RT
D9: ='Page 36'!E10 -> 1 | E9: ='Page 36'!F10 -> 0 | F9: ='Page 36'!G10 -> 0 | G9: ='Page 36'!H10 -> 0 | H9: ='Page 36'!I10 -> BLSR976 | I9: ='Page 36'!J10 -> 421+98.90 | J9: ='Page 36'!K10 -> 421+98.90 | K9: ='Page 36'!L10 -> LT
D10: ='Page 36'!E11 -> 1 | E10: ='Page 36'!F11 -> 0 | F10: ='Page 36'!G11 -> 0 | G10: ='Page 36'!H11 -> 0 | H10: ='Page 36'!I11 -> BLSR976 | I10: ='Page 36'!J11 -> 422+41.59 | J10: ='Page 36'!K11 -> 422+41.59 | K10: ='Page 36'!L11 -> RT
D11: ='Page 36'!E12 -> 1 | E11: ='Page 36'!F12 -> 0 | F11: ='Page 36'!G12 -> 0 | G11: ='Page 36'!H12 -> 0 | H11: ='Page 36'!I12 -> BLSR976 | I11: ='Page 36'!J12 -> 422+42.65 | J11: ='Page 36'!K12 -> 422+42.65 | K11: ='Page 36'!L12 -> RT
A43: Sub-Total: | D43: =SUBTOTAL(109,D6:D42) -> 6 | E43: =SUBTOTAL(109,E6:E42) -> 0
C45: Date:

Sheet 0650 1 60_x0009_VEHICULAR TRAFFIC SIG
A1: Final Measure : 0650 1 60 VEHICULAR TRAFFIC SIGNAL, REMOVE-POLES TO REMAIN | N1: Ir a Indice
N2: Ir a Pag 36
A3: Pay Item Number | B3: Pay Item Description | C3: Units of Measure | D3: Quantity | F3: Total Quantity | H3: Location
D4: P | E4: F | F4: P | G4: F | H4: Alignment | I4: Beging Sta. | J4: End Sta. | K4: Side | L4: Description: | M4: Estimate#:
A5: Column1 | B5: Column2 | C5: Column3 | D5: Column4 | E5: Column5 | F5: Column6 | G5: Column7 | H5: Column8 | I5: Column9 | J5: Column10 | K5: Column11 | L5: Column12 | M5: Column13
A6: ='Page 36'!A13 -> 0650 1 60 | B6: ='Page 36'!B13 -> Vehicular Traffic Signal, Remove- Poles To Remain | C6: ='Page 36'!D13 -> AS | D6: ='Page 36'!E13 -> 1 | E6: ='Page 36'!F13 -> 0 | F6: ='Page 36'!G13 -> 9 | G6: ='Page 36'!H13 -> 0 | H6: ='Page 36'!I13 -> BLSR976 | I6: ='Page 36'!J13 -> 421+32.01 | J6: ='Page 36'!K13 -> 421+32.01 | K6: ='Page 36'!L13 -> LT
D7: ='Page 36'!E14 -> 1 | E7: ='Page 36'!F14 -> 0 | F7: ='Page 36'!G14 -> 0 | G7: ='Page 36'!H14 -> 0 | H7: ='Page 36'!I14 -> BLSR976 | I7: ='Page 36'!J14 -> 421+32.76 | J7: ='Page 36'!K14 -> 421+32.76 | K7: ='Page 36'!L14 -> RT
